<?xml version="1.0"?>
<robot xmlns:xacro="http://www.ros.org/wiki/xacro" >

    <xacro:include filename="inertial_macros.xacro"/>
    
    <material name="white">
        <color rgba="1 1 1 1" />
    </material>

    <material name="orange">
        <color rgba="1 0.3 0.1 1" />
    </material>

    <material name="blue">
        <color rgba="0.2 0.2 1 1" />
    </material>

    <material name="black">
        <color rgba="0 0 0 1" />
    </material>

    <material name="red">
        <color rgba="1 0 0 1" />
    </material>

    <!--  Base Link  -->

    <link name="base_link">

    </link>

    <!-- BASE_FOOTPRINT LINK -->

    <joint name="base_footprint_joint" type="fixed">
        <parent link="base_link"/>
        <child link="base_footprint"/>
        <origin xyz="0 0 0" rpy="0 0 0"/>
    </joint>

    <link name="base_footprint">
    </link>


    <!--  Chassis Link  -->

    <joint name="chassis_joint" type="fixed">
        <parent link="base_link"/>
        <child link="chassis"/>
        <origin xyz="-0.15 0 0"/>
    </joint>

    <link name="chassis">  
        <visual>
            <origin xyz="0.391 0 0.3"/>
            <geometry>
                <box size="0.782 0.83 0.6"/>
            </geometry>
            <material name="white"/>
        </visual>
        <collision>
            <origin xyz="0.391 0 0.3"/>
            <geometry>
                <box size="0.782 0.83 0.6"/>
            </geometry>
        </collision>
        <xacro:inertial_box mass="1.5" x="0.782" y="0.83" z="0.6">
            <origin xyz="0.391 0 0.3" rpy="0 0 0"/>
        </xacro:inertial_box>
    </link>

    <gazebo reference="chassis">
        <material>Gazebo/White</material>
    </gazebo>
    
    <!--  Left Wheel Link  -->

    <joint name="left_wheel_joint" type="continuous">
        <parent link="base_link"/>
        <child link="left_wheel"/>
        <origin xyz="0.567 0.4 0" rpy="-${pi/2} 0 0"/>
        <axis xyz="0 0 1"/>
    </joint>

    <link name="left_wheel">  
        <visual>
            <geometry>
                <cylinder radius="0.22" length="0.08"/>
            </geometry>
            <material name="blue"/>
        </visual>
        <collision>
            <geometry>
                <sphere radius="0.22"/>
            </geometry>
        </collision>
        <xacro:inertial_cylinder mass="0.2" length="0.08" radius="0.22">
            <origin xyz="0 0 0" rpy="0 0 0"/>
        </xacro:inertial_cylinder>
    </link>

    <gazebo reference="left_wheel">
        <material>Gazebo/Blue</material>
    </gazebo>
        
    <!--  Right Wheel Link  -->

    <joint name="right_wheel_joint" type="continuous">
        <parent link="base_link"/>
        <child link="right_wheel"/>
        <origin xyz="0.567 -0.4 0" rpy="${pi/2} 0 0"/>
        <axis xyz="0 0 -1"/>
    </joint>

    <link name="right_wheel">  
        <visual>
            <geometry>
                <cylinder radius="0.22" length="0.08"/>
            </geometry>
            <material name="blue"/>
        </visual>
        <collision>
            <geometry>
                <sphere radius="0.22"/>
            </geometry>
        </collision>
        <xacro:inertial_cylinder mass="0.2" length="0.08" radius="0.22">
            <origin xyz="0 0 0" rpy="0 0 0"/>
        </xacro:inertial_cylinder>
    </link>

    <gazebo reference="right_wheel">
        <material>Gazebo/Blue</material>
        
    </gazebo>

    <!--  Left Caster Wheel Link  -->

    <joint name="left_caster_wheel_joint" type="fixed">
        <parent link="chassis"/>
        <child link="left_caster_wheel"/>
        <origin xyz="0 -0.35 0"/>
    </joint>

    <link name="left_caster_wheel">  
        <visual>
            <geometry>
                <sphere radius="0.22"/>
            </geometry>
            <material name="black"/>
        </visual>
        <collision>
            <geometry>
                <sphere radius="0.22"/>
            </geometry>
        </collision>
        <xacro:inertial_sphere mass="0.15" radius="0.22">
            <origin xyz="0 0 0" rpy="0 0 0"/>
        </xacro:inertial_sphere>
    </link>

    <gazebo reference="left_caster_wheel">
        <material>Gazebo/Black</material>
        <mu1 value="0.001"/>
        <mu2 value="0.001"/>
    </gazebo>

    <!--  Right Caster Wheel Link  -->

    <joint name="right_caster_wheel_joint" type="fixed">
        <parent link="chassis"/>
        <child link="right_caster_wheel"/>
        <origin xyz="0 0.35 0"/>
    </joint>

    <link name="right_caster_wheel">  
        <visual>
            <geometry>
                <sphere radius="0.22"/>
            </geometry>
            <material name="black"/>
        </visual>
        <collision>
            <geometry>
                <sphere radius="0.22"/>
            </geometry>
        </collision>
        <xacro:inertial_sphere mass="0.15" radius="0.22">
            <origin xyz="0 0 0" rpy="0 0 0"/>
        </xacro:inertial_sphere>
    </link>

    <gazebo reference="right_caster_wheel">
        <material>Gazebo/Black</material>
        <mu1 value="0.001"/>
        <mu2 value="0.001"/>
    </gazebo>
    

</robot>
